<sdf version='1.5'>
  <world name='default'>
    <light name='sun' type='directional'>
      <cast_shadows>1</cast_shadows>
      <pose>0 0 10 0 -0 0</pose>
      <diffuse>0.8 0.8 0.8 1</diffuse>
      <specular>0.2 0.2 0.2 1</specular>
      <attenuation>
        <range>1000</range>
        <constant>0.9</constant>
        <linear>0.01</linear>
        <quadratic>0.001</quadratic>
      </attenuation>
      <direction>-0.5 0.1 -0.9</direction>
    </light>
    <model name='ground_plane'>
      <static>1</static>
      <link name='link'>
        <collision name='collision'>
          <geometry>
            <plane>
              <normal>0 0 1</normal>
              <size>100 100</size>
            </plane>
          </geometry>
          <surface>
            <friction>
              <ode>
                <mu>100</mu>
                <mu2>50</mu2>
              </ode>
            </friction>
            <contact>
              <ode/>
            </contact>
            <bounce/>
          </surface>
          <max_contacts>10</max_contacts>
        </collision>
        <visual name='visual'>
          <cast_shadows>0</cast_shadows>
          <geometry>
            <plane>
              <normal>0 0 1</normal>
              <size>100 100</size>
            </plane>
          </geometry>
          <material>
            <script>
              <uri>file://media/materials/scripts/gazebo.material</uri>
              <name>Gazebo/Grey</name>
            </script>
          </material>
        </visual>
        <self_collide>0</self_collide>
        <kinematic>0</kinematic>
        <gravity>1</gravity>
      </link>
    </model>
    <physics name='default_physics' default='0' type='ode'>
      <max_step_size>0.001</max_step_size>
      <real_time_factor>1</real_time_factor>
      <real_time_update_rate>1000</real_time_update_rate>
      <gravity>0 0 -9.8</gravity>
      <magnetic_field>5.5645e-06 2.28758e-05 -4.23884e-05</magnetic_field>
    </physics>
    <scene>
      <ambient>0.4 0.4 0.4 1</ambient>
      <background>0.7 0.7 0.7 1</background>
      <shadows>1</shadows>
    </scene>
    <spherical_coordinates>
      <surface_model>EARTH_WGS84</surface_model>
      <latitude_deg>0</latitude_deg>
      <longitude_deg>0</longitude_deg>
      <elevation>0</elevation>
      <heading_deg>0</heading_deg>
    </spherical_coordinates>
    <state world_name='default'>
      <sim_time>806 79000000</sim_time>
      <real_time>52 340480765</real_time>
      <wall_time>1427454837 685092761</wall_time>
      <model name='ground_plane'>
        <pose>0 0 0 0 -0 0</pose>
        <link name='link'>
          <pose>0 0 0 0 -0 0</pose>
          <velocity>0 0 0 0 -0 0</velocity>
          <acceleration>0 0 0 0 -0 0</acceleration>
          <wrench>0 0 0 0 -0 0</wrench>
        </link>
      </model>
      <model name='polaris_ranger_xp900'>
        <static>1</static>
        <pose>1.31365 -1.61834 -0.027886 -4.7e-05 6.4e-05 -0.001629</pose>
        <link name='FNR_switch'>
          <pose>1.85388 -1.51917 1.12207 -4.8e-05 0.169644 -0.001637</pose>
          <velocity>-0.001367 0.004001 -0.006284 -0.004637 -0.001517 0.00021</velocity>
          <acceleration>-0.038399 0.01546 -0.000108 -0.032272 1e-05 -0.022328</acceleration>
          <wrench>-0.00384 0.001546 -1.1e-05 0 -0 0</wrench>
        </link>
        <link name='brake_pedal'>
          <pose>2.02272 -1.34947 0.510896 -4.8e-05 6.5e-05 -0.001629</pose>
          <velocity>-0.000416 0.001201 -0.00678 -0.004606 -0.001744 0.000252</velocity>
          <acceleration>-0.005471 -0.007885 -0.020146 -0.003639 0.000656 -0.002788</acceleration>
          <wrench>-0.000547 -0.000788 -0.002015 0 -0 0</wrench>
        </link>
        <link name='chassis'>
          <pose>1.31365 -1.61834 -0.027886 -4.7e-05 6.4e-05 -0.001629</pose>
          <velocity>0.000544 -0.001421 -0.006728 -0.004591 -0.001635 0.000207</velocity>
          <acceleration>-0.036998 0.000931 0.000805 -0.006318 -0.004359 -0.017291</acceleration>
          <wrench>-26.6389 0.670164 0.579347 0 -0 0</wrench>
        </link>
        <link name='front_left_wheel'>
          <pose>2.48093 -0.907665 0.319167 -1.5198 -0.096122 0.161888</pose>
          <velocity>-0.000387 0.001089 -0.005239 -0.002913 -0.001319 -0.000485</velocity>
          <acceleration>-0.031066 -0.008805 -0.00407 -0.001405 -0.002917 0.004908</acceleration>
          <wrench>-0.372795 -0.105657 -0.048843 0 -0 0</wrench>
        </link>
        <link name='front_left_wheel_steering_block'>
          <pose>2.51671 -1.12028 0.327176 1.57077 7.1e-05 0.166709</pose>
          <velocity>-0.000459 0.00114 -0.003543 -0.003956 -0.001515 -0.000134</velocity>
          <acceleration>-0.011802 0.011984 0.007021 -0.023559 -0.004592 0.078048</acceleration>
          <wrench>-0.011802 0.011984 0.007021 0 -0 0</wrench>
        </link>
        <link name='front_right_wheel'>
          <pose>2.55056 -2.33297 0.319143 1.51996 0.00472 0.165041</pose>
          <velocity>-0.000799 0.000623 -0.011471 -0.004035 -0.001839 -0.002227</velocity>
          <acceleration>-0.687183 -0.320217 0.105215 0.030498 -0.059111 -0.200901</acceleration>
          <wrench>-8.24619 -3.8426 1.26258 0 -0 0</wrench>
        </link>
        <link name='front_right_wheel_steering_block'>
          <pose>2.51509 -2.12029 0.327324 1.57075 7.1e-05 0.165276</pose>
          <velocity>-0.000578 0.000897 -0.014688 -0.003238 -0.001357 -0.001255</velocity>
          <acceleration>-0.478384 -0.105481 0.109014 -0.040896 -0.002997 -1.02211</acceleration>
          <wrench>-0.478384 -0.105481 0.109014 0 -0 0</wrench>
        </link>
        <link name='gas_pedal'>
          <pose>2.00041 -1.51944 0.495497 -4.7e-05 6.5e-05 -0.001629</pose>
          <velocity>-0.000341 0.001126 -0.006038 -0.00463 -0.001706 0.000217</velocity>
          <acceleration>-0.029925 -0.007865 -0.004258 -0.004712 0.009954 -0.003624</acceleration>
          <wrench>-0.002992 -0.000786 -0.000426 0 -0 0</wrench>
        </link>
        <link name='hand_brake'>
          <pose>1.84405 -1.41416 1.02207 -4.7e-05 -0.084115 -0.001625</pose>
          <velocity>-0.001224 0.003535 -0.006787 -0.004638 -0.001583 0.000211</velocity>
          <acceleration>-0.035498 0.012449 -0.003556 -0.006456 6.7e-05 -0.002233</acceleration>
          <wrench>-0.017749 0.006224 -0.001778 0 -0 0</wrench>
        </link>
        <link name='rear_left_wheel'>
          <pose>0.321066 -0.901095 0.319117 -1.52003 -0.044245 -0.003839</pose>
          <velocity>-0.000165 0.0005 -0.012025 0.000364 -0.000688 -0.000466</velocity>
          <acceleration>-0.014571 0.020623 -0.023204 -0.00253 -0.005112 0.001899</acceleration>
          <wrench>-0.174856 0.247471 -0.278444 0 -0 0</wrench>
        </link>
        <link name='rear_right_wheel'>
          <pose>0.318731 -2.33233 0.319181 1.51988 -0.050356 0.000898</pose>
          <velocity>0.000143 0.000245 -0.004904 -0.001578 0.000421 5.2e-05</velocity>
          <acceleration>-0.04902 0.020732 0.016814 -0.002581 -0.002322 -0.001869</acceleration>
          <wrench>-0.588243 0.248789 0.201765 0 -0 0</wrench>
        </link>
        <link name='steering_wheel'>
          <pose>1.73447 -1.15897 1.17206 -0.097216 -0.865926 0.125674</pose>
          <velocity>-0.001526 0.004208 -0.008151 -0.003664 -0.001653 -0.000612</velocity>
          <acceleration>-0.030631 0.019736 -0.012413 0.000153 -6.7e-05 -0.001449</acceleration>
          <wrench>-0.030631 0.019736 -0.012413 0 -0 0</wrench>
        </link>
      </model>
    </state>
    <gui fullscreen='0'>
      <camera name='user_camera'>
        <pose>0.03422 6.89356 4.26405 -2.86879e-17 0.255642 -1.60374</pose>
        <view_controller>orbit</view_controller>
      </camera>
    </gui>
    <model name='polaris_ranger_xp900'>
      <link name='chassis'>
        <inertial>
          <mass>720</mass>
          <inertia>
            <ixx>140</ixx>
            <ixy>0</ixy>
            <iyy>550</iyy>
            <ixz>0</ixz>
            <iyz>0</iyz>
            <izz>550</izz>
          </inertia>
          <pose>0.1 0 0.4 0 -0 0</pose>
        </inertial>
        <visual name='visual'>
          <pose>0 0 0 0 0 -1.5708</pose>
          <geometry>
            <mesh>
              <uri>model://polaris_ranger_xp900/meshes/polaris.dae</uri>
              <submesh>
                <name>Body</name>
                <center>0</center>
              </submesh>
            </mesh>
          </geometry>
          <material>
            <script>
              <uri>model://polaris_ranger_xp900/materials/scripts</uri>
              <uri>model://polaris_ranger_xp900/materials/textures</uri>
              <name>PolarisXP900/Diffuse</name>
            </script>
          </material>
        </visual>
        <collision name='chassis_bottom'>
          <pose>0.2 0 0.335 0 -0 0</pose>
          <geometry>
            <box>
              <size>1.34 1.65746 0.06</size>
            </box>
          </geometry>
          <max_contacts>10</max_contacts>
          <surface>
            <contact>
              <ode/>
            </contact>
            <bounce/>
            <friction>
              <ode/>
            </friction>
          </surface>
        </collision>
        <collision name='cargo_bottom'>
          <pose>-1 0 0.921 0 -0 0</pose>
          <geometry>
            <box>
              <size>1.04609 1.6998 0.01</size>
            </box>
          </geometry>
          <max_contacts>10</max_contacts>
          <surface>
            <contact>
              <ode/>
            </contact>
            <bounce/>
            <friction>
              <ode/>
            </friction>
          </surface>
        </collision>
        <collision name='cargo_front'>
          <pose>-0.495 0 1.06 0 -0 0</pose>
          <geometry>
            <box>
              <size>0.05 1.69982 0.27</size>
            </box>
          </geometry>
          <max_contacts>10</max_contacts>
          <surface>
            <contact>
              <ode/>
            </contact>
            <bounce/>
            <friction>
              <ode/>
            </friction>
          </surface>
        </collision>
        <collision name='cargo_back'>
          <pose>-1.465 0 1.06 0 -0 0</pose>
          <geometry>
            <box>
              <size>0.05 1.69982 0.27</size>
            </box>
          </geometry>
          <max_contacts>10</max_contacts>
          <surface>
            <contact>
              <ode/>
            </contact>
            <bounce/>
            <friction>
              <ode/>
            </friction>
          </surface>
        </collision>
        <collision name='cargo_left'>
          <pose>-0.97 0.82491 1.06 0 -0 0</pose>
          <geometry>
            <box>
              <size>1.04609 0.05 0.27</size>
            </box>
          </geometry>
          <max_contacts>10</max_contacts>
          <surface>
            <contact>
              <ode/>
            </contact>
            <bounce/>
            <friction>
              <ode/>
            </friction>
          </surface>
        </collision>
        <collision name='cargo_right'>
          <pose>-0.97 -0.82491 1.06 0 -0 0</pose>
          <geometry>
            <box>
              <size>1.04609 0.05 0.27</size>
            </box>
          </geometry>
          <max_contacts>10</max_contacts>
          <surface>
            <contact>
              <ode/>
            </contact>
            <bounce/>
            <friction>
              <ode/>
            </friction>
          </surface>
        </collision>
        <collision name='seat'>
          <pose>0 0 0.62 0 -0 0</pose>
          <geometry>
            <box>
              <size>0.52167 1.37206 0.38369</size> <!-- z was 0.53... -->
            </box>
          </geometry>
          <surface>
            <contact>
              <ode>
                <min_depth>0.01</min_depth>
              </ode>
            </contact>
            <bounce/>
            <friction>
	          <ode>
	            <mu>10000</mu>
	            <mu2>10000</mu2>
	          </ode>
        	</friction>
          </surface>
          <max_contacts>10</max_contacts>
        </collision>
        <!-- <collision name='mud_seat'>
          <pose>0 0 0.86 0 -0 0</pose>
          <geometry>
            <box>
              <size>0.52167 1.3 0.1</size>
            </box>
          </geometry>
          <surface>
            <contact>
              <collide_without_contact>1</collide_without_contact>
              <ode/>
            </contact>
            <bounce/>
            <friction>
              <ode/>
            </friction>
          </surface>
          <max_contacts>10</max_contacts>
        </collision> -->
        <!--<sensor name='seat_contact' type='contact'>
          <always_on>1</always_on>
          <update_rate>1000</update_rate>
          <contact>
            <collision>mud_seat</collision>
            <topic>__default_topic__</topic>
          </contact>
        </sensor>-->
        <collision name='seat_back'>
          <pose>-0.26 0 1.125 0 -0.2 0</pose>
          <geometry>
            <box>
              <size>0.06 1.37206 0.6</size>
            </box>
          </geometry>
          <max_contacts>10</max_contacts>
          <surface>
            <contact>
              <ode/>
            </contact>
            <bounce/>
            <friction>
              <ode/>
            </friction>
          </surface>
        </collision>
        <collision name='engine'>
          <pose>1.12 0 0.7 0 -0 0</pose>
          <geometry>
            <box>
              <size>0.58 1.3 0.8</size>
            </box>
          </geometry>
          <max_contacts>10</max_contacts>
          <surface>
            <contact>
              <ode/>
            </contact>
            <bounce/>
            <friction>
              <ode/>
            </friction>
          </surface>
        </collision>
<!--         <collision name='rollcage_top_left'>
          <pose>-0.02 0.76 1.936 3.14159 1.54159 3.14159</pose>
          <geometry>
            <cylinder>
              <radius>0.03</radius>
              <length>0.68</length>
            </cylinder>
          </geometry>
          <max_contacts>10</max_contacts>
          <surface>
            <contact>
              <ode/>
            </contact>
            <bounce/>
            <friction>
              <ode/>
            </friction>
          </surface>
        </collision>
        <collision name='rollcage_top_right'>
          <pose>-0.02 -0.76 1.936 3.14159 1.54159 3.14159</pose>
          <geometry>
            <cylinder>
              <radius>0.03</radius>
              <length>0.68</length>
            </cylinder>
          </geometry>
          <max_contacts>10</max_contacts>
          <surface>
            <contact>
              <ode/>
            </contact>
            <bounce/>
            <friction>
              <ode/>
            </friction>
          </surface>
        </collision>
        <collision name='rollcage_top_front'>
          <pose>0.315 0 1.93 0 -1 0</pose>
          <geometry>
            <box>
              <size>0.01299 1.54 0.10226</size>
            </box>
          </geometry>
          <max_contacts>10</max_contacts>
          <surface>
            <contact>
              <ode/>
            </contact>
            <bounce/>
            <friction>
              <ode/>
            </friction>
          </surface>
        </collision> -->
        <collision name='rollcage_top_back'>
          <pose>-0.41 0 1.88 0 -0 0</pose>
          <geometry>
            <box>
              <size>0.01299 1.54 0.10226</size>
            </box>
          </geometry>
          <max_contacts>10</max_contacts>
          <surface>
            <contact>
              <ode/>
            </contact>
            <bounce/>
            <friction>
              <ode/>
            </friction>
          </surface>
        </collision>
        <!-- <collision name='rollcage_front_left'>
          <pose>0.602 0.755 1.45 0 -0.54 0</pose>
          <geometry>
            <cylinder>
              <radius>0.03</radius>
              <length>1.15</length>
            </cylinder>
          </geometry>
          <max_contacts>10</max_contacts>
          <surface>
            <contact>
              <ode/>
            </contact>
            <bounce/>
            <friction>
              <ode/>
            </friction>
          </surface>
        </collision>
        <collision name='rollcage_front_right'>
          <pose>0.602 -0.755 1.45 0 -0.54 0</pose>
          <geometry>
            <cylinder>
              <radius>0.03</radius>
              <length>1.15</length>
            </cylinder>
          </geometry>
          <max_contacts>10</max_contacts>
          <surface>
            <contact>
              <ode/>
            </contact>
            <bounce/>
            <friction>
              <ode/>
            </friction>
          </surface>
        </collision> -->
        <collision name='rollcage_back_left'>
          <pose>-0.4 0.755 1.45 0 -0 0</pose>
          <geometry>
            <cylinder>
              <radius>0.03</radius>
              <length>1</length>
            </cylinder>
          </geometry>
          <max_contacts>10</max_contacts>
          <surface>
            <contact>
              <ode/>
            </contact>
            <bounce/>
            <friction>
              <ode/>
            </friction>
          </surface>
        </collision>
        <collision name='rollcage_back_right'>
          <pose>-0.4 -0.755 1.45 0 -0 0</pose>
          <geometry>
            <cylinder>
              <radius>0.03</radius>
              <length>1</length>
            </cylinder>
          </geometry>
          <max_contacts>10</max_contacts>
          <surface>
            <contact>
              <ode/>
            </contact>
            <bounce/>
            <friction>
              <ode/>
            </friction>
          </surface>
        </collision>
        <collision name='rollcage_X_1'>
          <pose>-0.411 0.04 1.445 0.397 -0 0</pose>
          <geometry>
            <box>
              <size>0.01392 1.55724 0.078</size>
            </box>
          </geometry>
          <max_contacts>10</max_contacts>
          <surface>
            <contact>
              <ode/>
            </contact>
            <bounce/>
            <friction>
              <ode/>
            </friction>
          </surface>
        </collision>
        <collision name='rollcage_X_2'>
          <pose>-0.4 -0.04 1.445 -0.397 0 0</pose>
          <geometry>
            <box>
              <size>0.01392 1.55724 0.078</size>
            </box>
          </geometry>
          <max_contacts>10</max_contacts>
          <surface>
            <contact>
              <ode/>
            </contact>
            <bounce/>
            <friction>
              <ode/>
            </friction>
          </surface>
        </collision>
        <!-- <collision name='central_hump1_collision'>
          <pose>0.55 -0.1 0.4 0 -0 0</pose>
          <geometry>
            <box>
              <size>0.6 0.15 0.1</size>
            </box>
          </geometry>
          <max_contacts>10</max_contacts>
          <surface>
            <contact>
              <ode/>
            </contact>
            <bounce/>
            <friction>
              <ode/>
            </friction>
          </surface>
        </collision>
        <collision name='central_hump2_collision'>
          <pose>0.7 -0.05 0.45 0 -0.5 0</pose>
          <geometry>
            <box>
              <size>0.2 0.05 0.1</size>
            </box>
          </geometry>
          <max_contacts>10</max_contacts>
          <surface>
            <contact>
              <ode/>
            </contact>
            <bounce/>
            <friction>
              <ode/>
            </friction>
          </surface>
        </collision>
        <collision name='central_hump3_collision'>
          <pose>0.798 -0.125 0.478 0 -0.8 0</pose>
          <geometry>
            <box>
              <size>0.129 0.1 0.05</size>
            </box>
          </geometry>
          <max_contacts>10</max_contacts>
          <surface>
            <contact>
              <ode/>
            </contact>
            <bounce/>
            <friction>
              <ode/>
            </friction>
          </surface>
        </collision>
        <collision name='central_hump4_collision'>
          <pose>0.8135 -0.05 0.45 0 -0 0</pose>
          <geometry>
            <box>
              <size>0.1 0.05 0.1835</size>
            </box>
          </geometry>
          <max_contacts>10</max_contacts>
          <surface>
            <contact>
              <ode/>
            </contact>
            <bounce/>
            <friction>
              <ode/>
            </friction>
          </surface>
        </collision>
        <collision name='central_hump5_collision'>
          <pose>0.84 -0.125 0.45 0 -0 0</pose>
          <geometry>
            <box>
              <size>0.03 0.1 0.1835</size>
            </box>
          </geometry>
          <max_contacts>10</max_contacts>
          <surface>
            <contact>
              <ode/>
            </contact>
            <bounce/>
            <friction>
              <ode/>
            </friction>
          </surface>
        </collision>
        <collision name='central_hump6_collision'>
          <pose>0.82 -0.125 0.475 0 -0 0</pose>
          <geometry>
            <box>
              <size>0.03 0.1 0.05</size>
            </box>
          </geometry>
          <max_contacts>10</max_contacts>
          <surface>
            <contact>
              <ode/>
            </contact>
            <bounce/>
            <friction>
              <ode/>
            </friction>
          </surface>
        </collision> -->
        <visual name='cargo_visual'>
          <pose>-1 0 1.0323 0 0 -1.5707</pose>
          <geometry>
            <mesh>
              <uri>model://polaris_ranger_xp900/meshes/polaris.dae</uri>
              <submesh>
                <name>Bed</name>
                <center>1</center>
              </submesh>
            </mesh>
          </geometry>
          <material>
            <script>
              <uri>model://polaris_ranger_xp900/materials/scripts</uri>
              <uri>model://polaris_ranger_xp900/materials/textures</uri>
              <name>PolarisXP900/Diffuse</name>
            </script>
          </material>
        </visual>
        <visual name='tailgate_visual'>
          <pose>-1.492 0 1.03 0 0 -1.5707</pose>
          <geometry>
            <mesh>
              <uri>model://polaris_ranger_xp900/meshes/polaris.dae</uri>
              <submesh>
                <name>Tail_Gate</name>
                <center>1</center>
              </submesh>
            </mesh>
          </geometry>
          <material>
            <script>
              <uri>model://polaris_ranger_xp900/materials/scripts</uri>
              <uri>model://polaris_ranger_xp900/materials/textures</uri>
              <name>PolarisXP900/Diffuse</name>
            </script>
          </material>
        </visual>
        <visual name='front_left_brake_visual'>
          <pose>1.12 -0.57488 0.35516 3.1415 -6.77626e-21 1.5707</pose>
          <geometry>
            <mesh>
              <uri>model://polaris_ranger_xp900/meshes/polaris.dae</uri>
              <submesh>
                <name>Brake_Front_Left</name>
                <center>1</center>
              </submesh>
            </mesh>
          </geometry>
          <material>
            <script>
              <uri>model://polaris_ranger_xp900/materials/scripts</uri>
              <uri>model://polaris_ranger_xp900/materials/textures</uri>
              <name>PolarisXP900/Diffuse</name>
            </script>
          </material>
        </visual>
        <visual name='front_right_brake_visual'>
          <pose>1.12 0.57488 0.35516 3.1415 -6.77626e-21 1.5707</pose>
          <geometry>
            <mesh>
              <uri>model://polaris_ranger_xp900/meshes/polaris.dae</uri>
              <submesh>
                <name>Brake_Front_Right</name>
                <center>1</center>
              </submesh>
            </mesh>
          </geometry>
          <material>
            <script>
              <uri>model://polaris_ranger_xp900/materials/scripts</uri>
              <uri>model://polaris_ranger_xp900/materials/textures</uri>
              <name>PolarisXP900/Diffuse</name>
            </script>
          </material>
        </visual>
        <visual name='central_hump1'>
          <pose>0.55 -0.1 0.4 0 -0 0</pose>
          <geometry>
            <box>
              <size>0.6 0.15 0.1</size>
            </box>
          </geometry>
          <material>
            <script>
              <uri>file://media/materials/scripts/gazebo.material</uri>
              <name>Gazebo/DarkGrey</name>
            </script>
          </material>
        </visual>
        <visual name='central_hump2'>
          <pose>0.7 -0.05 0.45 0 -0.5 0</pose>
          <geometry>
            <box>
              <size>0.2 0.05 0.1</size>
            </box>
          </geometry>
          <material>
            <script>
              <uri>file://media/materials/scripts/gazebo.material</uri>
              <name>Gazebo/DarkGrey</name>
            </script>
          </material>
        </visual>
        <visual name='central_hump3'>
          <pose>0.798 -0.125 0.478 0 -0.8 0</pose>
          <geometry>
            <box>
              <size>0.129 0.1 0.05</size>
            </box>
          </geometry>
          <material>
            <script>
              <uri>file://media/materials/scripts/gazebo.material</uri>
              <name>Gazebo/DarkGrey</name>
            </script>
          </material>
        </visual>
        <visual name='central_hump4'>
          <pose>0.8135 -0.05 0.45 0 -0 0</pose>
          <geometry>
            <box>
              <size>0.1 0.05 0.1835</size>
            </box>
          </geometry>
          <material>
            <script>
              <uri>file://media/materials/scripts/gazebo.material</uri>
              <name>Gazebo/DarkGrey</name>
            </script>
          </material>
        </visual>
        <visual name='central_hump5'>
          <pose>0.84 -0.125 0.45 0 -0 0</pose>
          <geometry>
            <box>
              <size>0.03 0.1 0.1835</size>
            </box>
          </geometry>
          <material>
            <script>
              <uri>file://media/materials/scripts/gazebo.material</uri>
              <name>Gazebo/DarkGrey</name>
            </script>
          </material>
        </visual>
        <visual name='central_hump6'>
          <pose>0.82 -0.125 0.475 0 -0 0</pose>
          <geometry>
            <box>
              <size>0.03 0.1 0.05</size>
            </box>
          </geometry>
          <material>
            <script>
              <uri>file://media/materials/scripts/gazebo.material</uri>
              <name>Gazebo/DarkGrey</name>
            </script>
          </material>
        </visual>
        <self_collide>0</self_collide>
        <kinematic>0</kinematic>
        <gravity>1</gravity>
      </link>
      <link name='front_left_wheel'>
        <pose>1.20223 0.71562 0.34697 -1.52 0 0</pose>
        <inertial>
          <mass>12</mass>
          <inertia>
            <ixx>0.5</ixx>
            <ixy>0</ixy>
            <iyy>0.5</iyy>
            <ixz>0</ixz>
            <iyz>0</iyz>
            <izz>1</izz>
          </inertia>
        </inertial>
        <collision name='collision'>
          <geometry>
            <cylinder>
              <radius>0.3175</radius>
              <length>0.2794</length>
            </cylinder>
          </geometry>
          <max_contacts>1</max_contacts>
          <surface>
            <friction>
              <ode>
                <mu>1</mu>
                <mu2>1</mu2>
                <fdir1>0 0 1</fdir1>
                <slip1>0</slip1>
                <slip2>0</slip2>
              </ode>
            </friction>
            <contact>
              <ode>
                <min_depth>0.005</min_depth>
                <kp>1e+08</kp>
              </ode>
            </contact>
            <bounce/>
          </surface>
        </collision>
        <visual name='tire_visual'>
          <pose>0 0 0 -2.65359e-06 1.57079 3.14159</pose>
          <geometry>
            <mesh>
              <uri>model://polaris_ranger_xp900/meshes/polaris.dae</uri>
              <scale>1.0037 0.8862 0.8862</scale>
              <submesh>
                <name>Wheel_Front_Left</name>
                <center>1</center>
              </submesh>
            </mesh>
          </geometry>
          <material>
            <script>
              <uri>model://polaris_ranger_xp900/materials/scripts</uri>
              <uri>model://polaris_ranger_xp900/materials/textures</uri>
              <name>PolarisXP900/Diffuse</name>
            </script>
          </material>
        </visual>
        <self_collide>0</self_collide>
        <kinematic>0</kinematic>
        <gravity>1</gravity>
      </link>
      <link name='front_right_wheel'>
        <pose>1.20223 -0.71562 0.34697 1.52 -0 0</pose>
        <inertial>
          <mass>12</mass>
          <inertia>
            <ixx>0.5</ixx>
            <ixy>0</ixy>
            <iyy>0.5</iyy>
            <ixz>0</ixz>
            <iyz>0</iyz>
            <izz>1</izz>
          </inertia>
        </inertial>
        <collision name='collision'>
          <geometry>
            <cylinder>
              <radius>0.3175</radius>
              <length>0.2794</length>
            </cylinder>
          </geometry>
          <max_contacts>1</max_contacts>
          <surface>
            <friction>
              <ode>
                <mu>1</mu>
                <mu2>1</mu2>
                <fdir1>0 0 1</fdir1>
                <slip1>0</slip1>
                <slip2>0</slip2>
              </ode>
            </friction>
            <contact>
              <ode>
                <min_depth>0.005</min_depth>
                <kp>1e+08</kp>
              </ode>
            </contact>
            <bounce/>
          </surface>
        </collision>
        <visual name='visual'>
          <pose>0 0 0 3.14159 -1.57079 3.14159</pose>
          <geometry>
            <mesh>
              <uri>model://polaris_ranger_xp900/meshes/polaris.dae</uri>
              <scale>1.0037 0.8862 0.8862</scale>
              <submesh>
                <name>Wheel_Front_Right</name>
                <center>1</center>
              </submesh>
            </mesh>
          </geometry>
          <material>
            <script>
              <uri>model://polaris_ranger_xp900/materials/scripts</uri>
              <uri>model://polaris_ranger_xp900/materials/textures</uri>
              <name>PolarisXP900/Diffuse</name>
            </script>
          </material>
        </visual>
        <self_collide>0</self_collide>
        <kinematic>0</kinematic>
        <gravity>1</gravity>
      </link>
      <link name='rear_left_wheel'>
        <pose>-0.99377 0.71562 0.34697 -1.52 0 0</pose>
        <inertial>
          <mass>12</mass>
          <inertia>
            <ixx>0.5</ixx>
            <ixy>0</ixy>
            <iyy>0.5</iyy>
            <ixz>0</ixz>
            <iyz>0</iyz>
            <izz>1</izz>
          </inertia>
        </inertial>
        <collision name='collision'>
          <geometry>
            <cylinder>
              <radius>0.3175</radius>
              <length>0.2794</length>
            </cylinder>
          </geometry>
          <max_contacts>1</max_contacts>
          <surface>
            <friction>
              <ode>
                <mu>1</mu>
                <mu2>1</mu2>
                <fdir1>0 0 1</fdir1>
                <slip1>0</slip1>
                <slip2>0</slip2>
              </ode>
            </friction>
            <contact>
              <ode>
                <min_depth>0.005</min_depth>
                <kp>1e+08</kp>
              </ode>
            </contact>
            <bounce/>
          </surface>
        </collision>
        <visual name='visual'>
          <pose>0 0 0 3.14159 -1.57079 3.14159</pose>
          <geometry>
            <mesh>
              <uri>model://polaris_ranger_xp900/meshes/polaris.dae</uri>
              <scale>1.0037 0.8862 0.8862</scale>
              <submesh>
                <name>Wheels_Rear_Left</name>
                <center>1</center>
              </submesh>
            </mesh>
          </geometry>
          <material>
            <script>
              <uri>model://polaris_ranger_xp900/materials/scripts</uri>
              <uri>model://polaris_ranger_xp900/materials/textures</uri>
              <name>PolarisXP900/Diffuse</name>
            </script>
          </material>
        </visual>
        <self_collide>0</self_collide>
        <kinematic>0</kinematic>
        <gravity>1</gravity>
      </link>
      <link name='rear_right_wheel'>
        <pose>-0.99377 -0.71562 0.34697 1.52 -0 0</pose>
        <inertial>
          <mass>12</mass>
          <inertia>
            <ixx>0.5</ixx>
            <ixy>0</ixy>
            <iyy>0.5</iyy>
            <ixz>0</ixz>
            <iyz>0</iyz>
            <izz>1</izz>
          </inertia>
        </inertial>
        <collision name='collision'>
          <geometry>
            <cylinder>
              <radius>0.3175</radius>
              <length>0.2794</length>
            </cylinder>
          </geometry>
          <max_contacts>1</max_contacts>
          <surface>
            <friction>
              <ode>
                <mu>1</mu>
                <mu2>1</mu2>
                <fdir1>0 0 1</fdir1>
                <slip1>0</slip1>
                <slip2>0</slip2>
              </ode>
            </friction>
            <contact>
              <ode>
                <min_depth>0.005</min_depth>
                <kp>1e+08</kp>
              </ode>
            </contact>
            <bounce/>
          </surface>
        </collision>
        <visual name='visual'>
          <pose>0 0 0 3.14159 -1.57079 3.14159</pose>
          <geometry>
            <mesh>
              <uri>model://polaris_ranger_xp900/meshes/polaris.dae</uri>
              <scale>1.0037 0.8862 0.8862</scale>
              <submesh>
                <name>Wheels_Rear_Right</name>
                <center>1</center>
              </submesh>
            </mesh>
          </geometry>
          <material>
            <script>
              <uri>model://polaris_ranger_xp900/materials/scripts</uri>
              <uri>model://polaris_ranger_xp900/materials/textures</uri>
              <name>PolarisXP900/Diffuse</name>
            </script>
          </material>
        </visual>
        <self_collide>0</self_collide>
        <kinematic>0</kinematic>
        <gravity>1</gravity>
      </link>
      <link name='gas_pedal'>
        <pose>0.63 0.1 0.58 0 -0 0</pose>
        <gravity>0</gravity>
        <inertial>
          <mass>0.1</mass>
          <pose>0 0 0 0 -0 0</pose>
          <inertia>
            <ixx>0.01</ixx>
            <ixy>0</ixy>
            <ixz>0</ixz>
            <iyy>0.01</iyy>
            <iyz>0</iyz>
            <izz>0.01</izz>
          </inertia>
        </inertial>
        <collision name='gas_pedal_collision'>
          <pose>-0.0385 0 -0.086 3.14159 1.12559 3.14159</pose>
          <geometry>
            <box>
              <size>0.1069 0.077 0.01</size>
            </box>
          </geometry>
          <max_contacts>10</max_contacts>
          <surface>
            <contact>
              <ode/>
            </contact>
            <bounce/>
            <friction>
              <ode/>
            </friction>
          </surface>
        </collision>
        <visual name='visual'>
          <pose>0 0 0 0 0 -1.5707</pose>
          <geometry>
            <mesh>
              <uri>model://polaris_ranger_xp900/meshes/polaris.dae</uri>
              <submesh>
                <name>Gas_Pedal</name>
                <center>1</center>
              </submesh>
            </mesh>
          </geometry>
          <material>
            <script>
              <uri>model://polaris_ranger_xp900/materials/scripts</uri>
              <uri>model://polaris_ranger_xp900/materials/textures</uri>
              <name>PolarisXP900/Diffuse</name>
            </script>
          </material>
        </visual>
        <self_collide>0</self_collide>
        <kinematic>0</kinematic>
      </link>
      <link name='brake_pedal'>
        <gravity>0</gravity>
        <pose>0.64 0.27 0.58 0 -0 0</pose>
        <inertial>
          <mass>0.1</mass>
          <pose>0 0 0 0 -0 0</pose>
          <inertia>
            <ixx>0.01</ixx>
            <ixy>0</ixy>
            <ixz>0</ixz>
            <iyy>0.01</iyy>
            <iyz>0</iyz>
            <izz>0.01</izz>
          </inertia>
        </inertial>
        <collision name='brake_pedal_collision'>
          <pose>-0.04 0 -0.086 3.14159 1.14259 3.14159</pose>
          <geometry>
            <box>
              <size>0.063 0.08 0.01</size>
            </box>
          </geometry>
          <max_contacts>10</max_contacts>
          <surface>
            <contact>
              <ode/>
            </contact>
            <bounce/>
            <friction>
              <ode/>
            </friction>
          </surface>
        </collision>
        <visual name='visual'>
          <pose>0 0 0 0 0 -1.5707</pose>
          <geometry>
            <mesh>
              <uri>model://polaris_ranger_xp900/meshes/polaris.dae</uri>
              <submesh>
                <name>Brake_Pedal</name>
                <center>1</center>
              </submesh>
            </mesh>
          </geometry>
          <material>
            <script>
              <uri>model://polaris_ranger_xp900/materials/scripts</uri>
              <uri>model://polaris_ranger_xp900/materials/textures</uri>
              <name>PolarisXP900/Diffuse</name>
            </script>
          </material>
        </visual>
        <self_collide>0</self_collide>
        <kinematic>0</kinematic>
      </link>
      <link name='front_right_wheel_steering_block'>
        <pose>1.20223 -0.5 0.35515 1.5708 -0 0</pose>
        <inertial>
          <mass>1</mass>
          <inertia>
            <ixx>1</ixx>
            <ixy>0</ixy>
            <iyy>1</iyy>
            <ixz>0</ixz>
            <iyz>0</iyz>
            <izz>1</izz>
          </inertia>
        </inertial>
        <collision name='collision'>
          <geometry>
            <cylinder>
              <radius>0.05</radius>
              <length>0.01</length>
            </cylinder>
          </geometry>
          <max_contacts>10</max_contacts>
          <surface>
            <contact>
              <ode/>
            </contact>
            <bounce/>
            <friction>
              <ode/>
            </friction>
          </surface>
        </collision>
        <self_collide>0</self_collide>
        <kinematic>0</kinematic>
        <gravity>1</gravity>
      </link>
      <link name='front_left_wheel_steering_block'>
        <pose>1.20223 0.5 0.35515 1.5708 -0 0</pose>
        <inertial>
          <mass>1</mass>
          <inertia>
            <ixx>1</ixx>
            <ixy>0</ixy>
            <iyy>1</iyy>
            <ixz>0</ixz>
            <iyz>0</iyz>
            <izz>1</izz>
          </inertia>
        </inertial>
        <collision name='collision'>
          <geometry>
            <cylinder>
              <radius>0.05</radius>
              <length>0.01</length>
            </cylinder>
          </geometry>
          <max_contacts>10</max_contacts>
          <surface>
            <contact>
              <ode/>
            </contact>
            <bounce/>
            <friction>
              <ode/>
            </friction>
          </surface>
        </collision>
        <self_collide>0</self_collide>
        <kinematic>0</kinematic>
        <gravity>1</gravity>
      </link>
      <link name='steering_wheel'>
        <pose>0.42 0.46 1.2 0 -0.87 0</pose>
        <inertial>
          <mass>1</mass>
          <pose>-0.002 0 0 0 -0 0</pose>
          <inertia>
            <ixx>0.012</ixx>
            <ixy>0</ixy>
            <ixz>0</ixz>
            <iyy>0.012</iyy>
            <iyz>0</iyz>
            <izz>0.024</izz>
          </inertia>
        </inertial>
        <!-- <collision name='collision'>
          <pose>-0.03 0 -0.120825 -0.6108 -5.55112e-17 -1.5708</pose>
          <geometry>
            <mesh>
              <uri>model://polaris_ranger_xp900/meshes/polaris.dae</uri>
              <submesh>
                <name>Steering_Wheel</name>
                <center>1</center>
              </submesh>
            </mesh>
          </geometry>
          <surface>
            <contact>
              <ode>
                <min_depth>0.003</min_depth>
              </ode>
            </contact>
            <bounce/>
            <friction>
              <ode/>
            </friction>
          </surface>
          <max_contacts>10</max_contacts>
        </collision> -->
        <visual name='visual'>
          <pose>-0.03 0 -0.120825 -0.6108 -5.55112e-17 -1.5708</pose>
          <geometry>
            <mesh>
              <uri>model://polaris_ranger_xp900/meshes/polaris.dae</uri>
              <submesh>
                <name>Steering_Wheel</name>
                <center>1</center>
              </submesh>
            </mesh>
          </geometry>
          <material>
           <script>
<uri>file://media/materials/scripts/gazebo.material</uri>
             <name>Gazebo/Wood</name>
           </script>
         </material>
          <!--<material>
            <script>
              <uri>model://polaris_ranger_xp900/materials/scripts</uri>
              <uri>model://polaris_ranger_xp900/materials/textures</uri>
              <name>PolarisXP900/Diffuse</name>
            </script>
          </material>-->
        </visual>
        <self_collide>0</self_collide>
        <kinematic>0</kinematic>
        <gravity>1</gravity>
      </link>
      <link name='hand_brake'>
        <pose>0.53 0.205 1.05 0 -0 0</pose>
        <inertial>
          <mass>0.5</mass>
          <inertia>
            <ixx>0.1</ixx>
            <ixy>0</ixy>
            <ixz>0</ixz>
            <iyy>0.1</iyy>
            <iyz>0</iyz>
            <izz>0.05</izz>
          </inertia>
        </inertial>
        <!-- <collision name='hand_brake_collision'>
          <pose>0 0 0.05 -0.2 -1.38778e-17 -1.5708</pose>
          <geometry>
            <mesh>
              <uri>model://polaris_ranger_xp900/meshes/polaris.dae</uri>
              <submesh>
                <name>Shifter</name>
                <center>1</center>
              </submesh>
            </mesh>
          </geometry>
          <max_contacts>10</max_contacts>
          <surface>
            <contact>
              <ode/>
            </contact>
            <bounce/>
            <friction>
              <ode/>
            </friction>
          </surface>
        </collision> -->
        <visual name='hand_brake_visual'>
          <pose>0 0 0.05 -0.2 -1.38778e-17 -1.5708</pose>
          <geometry>
            <mesh>
              <uri>model://polaris_ranger_xp900/meshes/polaris.dae</uri>
              <submesh>
                <name>Shifter</name>
                <center>1</center>
              </submesh>
            </mesh>
          </geometry>
          <material>
            <script>
              <uri>model://polaris_ranger_xp900/materials/scripts</uri>
              <uri>model://polaris_ranger_xp900/materials/textures</uri>
              <name>PolarisXP900/Diffuse</name>
            </script>
          </material>
        </visual>
        <self_collide>0</self_collide>
        <kinematic>0</kinematic>
        <gravity>1</gravity>
      </link>
      <link name='FNR_switch'>
        <pose>0.54 0.1 1.15 0 0.25 0</pose>
        <inertial>
          <mass>0.1</mass>
          <inertia>
            <ixx>0.1</ixx>
            <ixy>0</ixy>
            <ixz>0</ixz>
            <iyy>6e-05</iyy>
            <iyz>0</iyz>
            <izz>0.1</izz>
          </inertia>
        </inertial>
        <!-- <collision name='FNR_switch'>
          <geometry>
            <box>
              <size>0.02 0.04 0.08</size>
            </box>
          </geometry>
          <max_contacts>10</max_contacts>
          <surface>
            <contact>
              <ode/>
            </contact>
            <bounce/>
            <friction>
              <ode/>
            </friction>
          </surface>
        </collision> -->
        <visual name='FNR_switch_F'>
          <transparency>0</transparency>
          <geometry>
            <box>
              <size>0.02 0.04 0.08</size>
            </box>
          </geometry>
          <material>
            <script>
              <uri>model://polaris_ranger_ev/materials/scripts</uri>
              <uri>model://polaris_ranger_ev/materials/textures</uri>
              <name>FNR_switch_F</name>
            </script>
          </material>
        </visual>
        <visual name='FNR_switch_R'>
          <transparency>1</transparency>
          <geometry>
            <box>
              <size>0.0199 0.0399 0.0799</size>
            </box>
          </geometry>
          <material>
            <script>
              <uri>model://polaris_ranger_ev/materials/scripts</uri>
              <uri>model://polaris_ranger_ev/materials/textures</uri>
              <name>FNR_switch_R</name>
            </script>
          </material>
        </visual>
        <self_collide>0</self_collide>
        <kinematic>0</kinematic>
        <gravity>1</gravity>
      </link>
      <joint name='front_left_steering_joint' type='revolute'>
        <child>front_left_wheel_steering_block</child>
        <parent>chassis</parent>
        <axis>
          <xyz>0 0 1</xyz>
          <limit>
            <lower>-0.7727</lower>
            <upper>0.7727</upper>
          </limit>
          <dynamics>
            <damping>50</damping>
            <spring_reference>0</spring_reference>
            <spring_stiffness>0</spring_stiffness>
          </dynamics>
          <use_parent_model_frame>1</use_parent_model_frame>
        </axis>
        <physics>
          <ode>
            <cfm_damping>1</cfm_damping>
            <limit>
              <cfm>0</cfm>
              <erp>0.9</erp>
            </limit>
          </ode>
        </physics>
      </joint>
      <joint name='front_left_wheel_joint' type='revolute'>
        <child>front_left_wheel</child>
        <parent>front_left_wheel_steering_block</parent>
        <axis>
          <xyz>0 1 0.05</xyz>
          <use_parent_model_frame>1</use_parent_model_frame>
          <limit>
            <lower>-1e+16</lower>
            <upper>1e+16</upper>
          </limit>
          <dynamics>
            <spring_reference>0</spring_reference>
            <spring_stiffness>0</spring_stiffness>
          </dynamics>
        </axis>
      </joint>
      <joint name='front_right_steering_joint' type='revolute'>
        <child>front_right_wheel_steering_block</child>
        <parent>chassis</parent>
        <axis>
          <xyz>0 0 1</xyz>
          <limit>
            <lower>-0.7727</lower>
            <upper>0.7727</upper>
          </limit>
          <dynamics>
            <damping>50</damping>
            <spring_reference>0</spring_reference>
            <spring_stiffness>0</spring_stiffness>
          </dynamics>
          <use_parent_model_frame>1</use_parent_model_frame>
        </axis>
        <physics>
          <ode>
            <cfm_damping>1</cfm_damping>
            <limit>
              <cfm>0</cfm>
              <erp>0.9</erp>
            </limit>
          </ode>
        </physics>
      </joint>
      <joint name='front_right_wheel_joint' type='revolute'>
        <child>front_right_wheel</child>
        <parent>front_right_wheel_steering_block</parent>
        <axis>
          <xyz>0 1 -0.05</xyz>
          <use_parent_model_frame>1</use_parent_model_frame>
          <limit>
            <lower>-1e+16</lower>
            <upper>1e+16</upper>
          </limit>
          <dynamics>
            <spring_reference>0</spring_reference>
            <spring_stiffness>0</spring_stiffness>
          </dynamics>
        </axis>
      </joint>
      <joint name='rear_left_wheel_joint' type='revolute'>
        <child>rear_left_wheel</child>
        <parent>chassis</parent>
        <axis>
          <xyz>0 1 0.05</xyz>
          <use_parent_model_frame>1</use_parent_model_frame>
          <limit>
            <lower>-1e+16</lower>
            <upper>1e+16</upper>
          </limit>
          <dynamics>
            <spring_reference>0</spring_reference>
            <spring_stiffness>0</spring_stiffness>
          </dynamics>
        </axis>
      </joint>
      <joint name='rear_right_wheel_joint' type='revolute'>
        <pose>0 0 -0.1 0 -0 0</pose>
        <child>rear_right_wheel</child>
        <parent>chassis</parent>
        <axis>
          <xyz>0 1 -0.05</xyz>
          <use_parent_model_frame>1</use_parent_model_frame>
          <limit>
            <lower>-1e+16</lower>
            <upper>1e+16</upper>
          </limit>
          <dynamics>
            <spring_reference>0</spring_reference>
            <spring_stiffness>0</spring_stiffness>
          </dynamics>
        </axis>
      </joint>
      <joint name='rear_differential_joint' type='revolute'>
        <child>rear_right_wheel</child>
        <parent>rear_left_wheel</parent>
        <axis>
          <xyz>0 1 0</xyz>
          <dynamics>
            <damping>70</damping>
            <spring_reference>0</spring_reference>
            <spring_stiffness>0</spring_stiffness>
          </dynamics>
          <use_parent_model_frame>1</use_parent_model_frame>
          <limit>
            <lower>-1e+16</lower>
            <upper>1e+16</upper>
          </limit>
        </axis>
        <physics>
          <ode>
            <erp>0</erp>
            <cfm>1000</cfm>
            <cfm_damping>1</cfm_damping>
            <limit>
              <cfm>0</cfm>
              <erp>0.2</erp>
            </limit>
          </ode>
        </physics>
      </joint>
      <joint name='gas_joint' type='prismatic'>
        <parent>chassis</parent>
        <child>gas_pedal</child>
        <axis>
          <xyz>1 0 -1</xyz>
          <limit>
            <lower>0</lower>
            <upper>0.08</upper>
          </limit>
          <dynamics>
            <damping>3</damping>
            <spring_reference>0</spring_reference>
            <spring_stiffness>0</spring_stiffness>
          </dynamics>
          <use_parent_model_frame>1</use_parent_model_frame>
        </axis>
        <physics>
          <ode>
            <cfm_damping>1</cfm_damping>
            <limit>
              <cfm>0</cfm>
              <erp>0.2</erp>
            </limit>
          </ode>
        </physics>
      </joint>
      <joint name='brake_joint' type='prismatic'>
        <parent>chassis</parent>
        <child>brake_pedal</child>
        <axis>
          <xyz>1 0 -0.6</xyz>
          <limit>
            <lower>0</lower>
            <upper>0.08</upper>
          </limit>
          <dynamics>
            <damping>3</damping>
            <spring_reference>0</spring_reference>
            <spring_stiffness>0</spring_stiffness>
          </dynamics>
          <use_parent_model_frame>1</use_parent_model_frame>
        </axis>
        <physics>
          <ode>
            <cfm_damping>1</cfm_damping>
            <limit>
              <cfm>0</cfm>
              <erp>0.2</erp>
            </limit>
          </ode>
        </physics>
      </joint>
      <joint name='steering_joint' type='revolute'>
        <pose>0 0 0 0 -0 0</pose>
        <parent>chassis</parent>
        <child>steering_wheel</child>
        <axis>
          <xyz>-1 0 0.84365</xyz>
          <limit>
            <lower>-3.14</lower>
            <upper>3.14</upper>
          </limit>
          <dynamics>
            <damping>1</damping>
            <spring_reference>0</spring_reference>
            <spring_stiffness>0</spring_stiffness>
          </dynamics>
          <use_parent_model_frame>1</use_parent_model_frame>
        </axis>
        <physics>
          <ode>
            <cfm_damping>1</cfm_damping>
            <limit>
              <cfm>0</cfm>
              <erp>0.2</erp>
            </limit>
          </ode>
        </physics>
      </joint>
      <joint name='hand_brake_joint' type='revolute'>
        <parent>chassis</parent>
        <child>hand_brake</child>
        <axis>
          <xyz>0 -1 0</xyz>
          <limit>
            <lower>0</lower>
            <upper>0.6</upper>
          </limit>
          <dynamics>
            <damping>1</damping>
            <spring_reference>0</spring_reference>
            <spring_stiffness>0</spring_stiffness>
          </dynamics>
          <use_parent_model_frame>1</use_parent_model_frame>
        </axis>
        <physics>
          <ode>
            <cfm_damping>1</cfm_damping>
            <limit>
              <cfm>0</cfm>
              <erp>0.2</erp>
            </limit>
          </ode>
        </physics>
      </joint>
      <joint name='FNR_switch_joint' type='revolute'>
        <parent>chassis</parent>
        <child>FNR_switch</child>
        <axis>
          <xyz>0 -1 0</xyz>
          <limit>
            <lower>-0.3</lower>
            <upper>0.3</upper>
          </limit>
          <dynamics>
            <damping>0.01</damping>
            <spring_reference>0</spring_reference>
            <spring_stiffness>0</spring_stiffness>
          </dynamics>
          <use_parent_model_frame>1</use_parent_model_frame>
        </axis>
        <physics>
          <ode>
            <cfm_damping>1</cfm_damping>
            <limit>
              <cfm>0</cfm>
              <erp>0.2</erp>
            </limit>
          </ode>
        </physics>
      </joint>
      <pose>-0.592313 0.57392 0 0 -0 0</pose>
    </model>
  </world>
</sdf>
